2018-12-28 14:41:11,422 INFO: Microblob startup [in /Users/dandam/dev/microblob/app/__init__.py:43]
2018-12-28 14:41:47,442 INFO: Microblob startup [in /Users/dandam/dev/microblob/app/__init__.py:43]
2018-12-28 14:41:56,007 ERROR: Exception on /edit_profile [POST] [in /Users/dandam/dev/microblob/venv/lib/python3.7/site-packages/flask/app.py:1761]
Traceback (most recent call last):
  File "/Users/dandam/dev/microblob/venv/lib/python3.7/site-packages/sqlalchemy/engine/base.py", line 1193, in _execute_context
    context)
  File "/Users/dandam/dev/microblob/venv/lib/python3.7/site-packages/sqlalchemy/engine/default.py", line 509, in do_execute
    cursor.execute(statement, parameters)
sqlite3.IntegrityError: UNIQUE constraint failed: user.username

The above exception was the direct cause of the following exception:

Traceback (most recent call last):
  File "/Users/dandam/dev/microblob/venv/lib/python3.7/site-packages/flask/app.py", line 2292, in wsgi_app
    response = self.full_dispatch_request()
  File "/Users/dandam/dev/microblob/venv/lib/python3.7/site-packages/flask/app.py", line 1815, in full_dispatch_request
    rv = self.handle_user_exception(e)
  File "/Users/dandam/dev/microblob/venv/lib/python3.7/site-packages/flask/app.py", line 1718, in handle_user_exception
    reraise(exc_type, exc_value, tb)
  File "/Users/dandam/dev/microblob/venv/lib/python3.7/site-packages/flask/_compat.py", line 35, in reraise
    raise value
  File "/Users/dandam/dev/microblob/venv/lib/python3.7/site-packages/flask/app.py", line 1813, in full_dispatch_request
    rv = self.dispatch_request()
  File "/Users/dandam/dev/microblob/venv/lib/python3.7/site-packages/flask/app.py", line 1799, in dispatch_request
    return self.view_functions[rule.endpoint](**req.view_args)
  File "/Users/dandam/dev/microblob/venv/lib/python3.7/site-packages/flask_login/utils.py", line 261, in decorated_view
    return func(*args, **kwargs)
  File "/Users/dandam/dev/microblob/app/routes.py", line 84, in edit_profile
    db.session.commit()
  File "/Users/dandam/dev/microblob/venv/lib/python3.7/site-packages/sqlalchemy/orm/scoping.py", line 153, in do
    return getattr(self.registry(), name)(*args, **kwargs)
  File "/Users/dandam/dev/microblob/venv/lib/python3.7/site-packages/sqlalchemy/orm/session.py", line 954, in commit
    self.transaction.commit()
  File "/Users/dandam/dev/microblob/venv/lib/python3.7/site-packages/sqlalchemy/orm/session.py", line 467, in commit
    self._prepare_impl()
  File "/Users/dandam/dev/microblob/venv/lib/python3.7/site-packages/sqlalchemy/orm/session.py", line 447, in _prepare_impl
    self.session.flush()
  File "/Users/dandam/dev/microblob/venv/lib/python3.7/site-packages/sqlalchemy/orm/session.py", line 2313, in flush
    self._flush(objects)
  File "/Users/dandam/dev/microblob/venv/lib/python3.7/site-packages/sqlalchemy/orm/session.py", line 2440, in _flush
    transaction.rollback(_capture_exception=True)
  File "/Users/dandam/dev/microblob/venv/lib/python3.7/site-packages/sqlalchemy/util/langhelpers.py", line 66, in __exit__
    compat.reraise(exc_type, exc_value, exc_tb)
  File "/Users/dandam/dev/microblob/venv/lib/python3.7/site-packages/sqlalchemy/util/compat.py", line 249, in reraise
    raise value
  File "/Users/dandam/dev/microblob/venv/lib/python3.7/site-packages/sqlalchemy/orm/session.py", line 2404, in _flush
    flush_context.execute()
  File "/Users/dandam/dev/microblob/venv/lib/python3.7/site-packages/sqlalchemy/orm/unitofwork.py", line 395, in execute
    rec.execute(self)
  File "/Users/dandam/dev/microblob/venv/lib/python3.7/site-packages/sqlalchemy/orm/unitofwork.py", line 560, in execute
    uow
  File "/Users/dandam/dev/microblob/venv/lib/python3.7/site-packages/sqlalchemy/orm/persistence.py", line 177, in save_obj
    mapper, table, update)
  File "/Users/dandam/dev/microblob/venv/lib/python3.7/site-packages/sqlalchemy/orm/persistence.py", line 774, in _emit_update_statements
    execute(statement, multiparams)
  File "/Users/dandam/dev/microblob/venv/lib/python3.7/site-packages/sqlalchemy/engine/base.py", line 948, in execute
    return meth(self, multiparams, params)
  File "/Users/dandam/dev/microblob/venv/lib/python3.7/site-packages/sqlalchemy/sql/elements.py", line 269, in _execute_on_connection
    return connection._execute_clauseelement(self, multiparams, params)
  File "/Users/dandam/dev/microblob/venv/lib/python3.7/site-packages/sqlalchemy/engine/base.py", line 1060, in _execute_clauseelement
    compiled_sql, distilled_params
  File "/Users/dandam/dev/microblob/venv/lib/python3.7/site-packages/sqlalchemy/engine/base.py", line 1200, in _execute_context
    context)
  File "/Users/dandam/dev/microblob/venv/lib/python3.7/site-packages/sqlalchemy/engine/base.py", line 1413, in _handle_dbapi_exception
    exc_info
  File "/Users/dandam/dev/microblob/venv/lib/python3.7/site-packages/sqlalchemy/util/compat.py", line 265, in raise_from_cause
    reraise(type(exception), exception, tb=exc_tb, cause=cause)
  File "/Users/dandam/dev/microblob/venv/lib/python3.7/site-packages/sqlalchemy/util/compat.py", line 248, in reraise
    raise value.with_traceback(tb)
  File "/Users/dandam/dev/microblob/venv/lib/python3.7/site-packages/sqlalchemy/engine/base.py", line 1193, in _execute_context
    context)
  File "/Users/dandam/dev/microblob/venv/lib/python3.7/site-packages/sqlalchemy/engine/default.py", line 509, in do_execute
    cursor.execute(statement, parameters)
sqlalchemy.exc.IntegrityError: (sqlite3.IntegrityError) UNIQUE constraint failed: user.username [SQL: 'UPDATE user SET username=?, about_me=? WHERE user.id = ?'] [parameters: ('larry', 'Wrote a trilogy about Cairo. And another trilogy about ancient Cairo. And movies. And other books. I am not Larry.', 1)] (Background on this error at: http://sqlalche.me/e/gkpj)
2018-12-28 14:57:41,599 INFO: Microblob startup [in /Users/dandam/dev/microblob/app/__init__.py:43]
2018-12-28 14:57:58,666 INFO: Microblob startup [in /Users/dandam/dev/microblob/app/__init__.py:43]
2018-12-30 10:51:33,096 INFO: Microblob startup [in /Users/dandam/dev/microblob/app/__init__.py:43]
2018-12-30 10:55:15,936 INFO: Microblob startup [in /Users/dandam/dev/microblob/app/__init__.py:43]
2018-12-30 10:55:31,595 INFO: Microblob startup [in /Users/dandam/dev/microblob/app/__init__.py:43]
2018-12-30 10:55:53,294 INFO: Microblob startup [in /Users/dandam/dev/microblob/app/__init__.py:43]
2018-12-30 11:05:36,308 INFO: Microblob startup [in /Users/dandam/dev/microblob/app/__init__.py:43]
2018-12-30 11:08:26,607 INFO: Microblob startup [in /Users/dandam/dev/microblob/app/__init__.py:43]
2018-12-30 11:08:45,123 INFO: Microblob startup [in /Users/dandam/dev/microblob/app/__init__.py:43]
2018-12-30 11:09:21,739 INFO: Microblob startup [in /Users/dandam/dev/microblob/app/__init__.py:43]
2018-12-30 11:10:24,265 INFO: Microblob startup [in /Users/dandam/dev/microblob/app/__init__.py:43]
2018-12-30 11:10:48,219 INFO: Microblob startup [in /Users/dandam/dev/microblob/app/__init__.py:43]
2018-12-30 11:11:15,987 INFO: Microblob startup [in /Users/dandam/dev/microblob/app/__init__.py:43]
2018-12-30 11:39:54,071 INFO: Microblob startup [in /Users/dandam/dev/microblob/app/__init__.py:43]
2018-12-30 11:43:15,828 INFO: Microblob startup [in /Users/dandam/dev/microblob/app/__init__.py:43]
2018-12-30 11:44:00,354 INFO: Microblob startup [in /Users/dandam/dev/microblob/app/__init__.py:43]
2018-12-30 12:06:03,228 INFO: Microblob startup [in /Users/dandam/dev/microblob/app/__init__.py:43]
2018-12-30 12:06:21,963 INFO: Microblob startup [in /Users/dandam/dev/microblob/app/__init__.py:43]
2018-12-30 12:06:39,242 ERROR: Exception on /follow/larry [GET] [in /Users/dandam/dev/microblob/venv/lib/python3.7/site-packages/flask/app.py:1761]
Traceback (most recent call last):
  File "/Users/dandam/dev/microblob/venv/lib/python3.7/site-packages/flask/app.py", line 2292, in wsgi_app
    response = self.full_dispatch_request()
  File "/Users/dandam/dev/microblob/venv/lib/python3.7/site-packages/flask/app.py", line 1815, in full_dispatch_request
    rv = self.handle_user_exception(e)
  File "/Users/dandam/dev/microblob/venv/lib/python3.7/site-packages/flask/app.py", line 1718, in handle_user_exception
    reraise(exc_type, exc_value, tb)
  File "/Users/dandam/dev/microblob/venv/lib/python3.7/site-packages/flask/_compat.py", line 35, in reraise
    raise value
  File "/Users/dandam/dev/microblob/venv/lib/python3.7/site-packages/flask/app.py", line 1813, in full_dispatch_request
    rv = self.dispatch_request()
  File "/Users/dandam/dev/microblob/venv/lib/python3.7/site-packages/flask/app.py", line 1799, in dispatch_request
    return self.view_functions[rule.endpoint](**req.view_args)
  File "/Users/dandam/dev/microblob/venv/lib/python3.7/site-packages/flask_login/utils.py", line 261, in decorated_view
    return func(*args, **kwargs)
TypeError: follow() got an unexpected keyword argument 'username'
2018-12-30 12:07:56,650 INFO: Microblob startup [in /Users/dandam/dev/microblob/app/__init__.py:43]
